Workbook
Name cop: #REF!

Sheet data
A1: Customer_ID | B1: First_Name | C1: Last_Name | D1: Age | E1: Gender | F1: City | G1: Email | H1: Address | I1: Order_ID | J1: Order_Date | K1: Order_Time | L1: Product_ID | M1: Price | N1: Quantity | O1: Coupon_Code | P1: Estimated_Days_to_Deliver | Q1: Delivery_Charge | R1: Delivery_Date | S1: Delivery_Time | T1: Days_to_Deliver | U1: Amount | V1: Amount_with_Del_Charge | W1: Discount_Percent | X1: Final_Amount | Y1: Full_Name | Z1: IsLateDelivery | AA1: Email_Domain
A2: CID186 | B2: Anne | C2: Oconnell | D2: 37 | E2: Male | F2: Phoenix | G2: anne.oconnell@outlook.com | H2: 2850 Matthew Ford, North Yolandachester, FL 67488 | I2: OID2497 | J2: 45358 | K2: 18:16:33 | L2: PID022 | M2: 308.88 | N2: 5 | O2: FLAT8 | P2: 4 | Q2: 60 | R2: 45361 | S2: 08:51:31 | T2: =R2-J2 -> 3 | U2: =M2*N2 -> 1544.4 | V2: =U2+Q2 -> 1604.4 | W2: =IF(O2="FLAT8",0.08,IF(O2="FLAT10",0.1,IF(O2="FLAT15",0.15,IF(O2="FLAT20",0.2,0)))) -> 0.08 | X2: =V2*(1-W2) -> 1476.048 | Y2: =B2&" "&C2 -> Anne Oconnell | Z2: =IF(T2>P2,"Late",IF(T2<P2,"BeforeTime","Intime")) -> BeforeTime | AA2: =MID(G2,FIND("@",G2)+1,LEN(G2)-FIND("@",G2)) -> outlook.com
A3: CID150 | B3: Anthony | C3: Thomas | D3: 53 | E3: Female | F3: Houston | G3: anthony.thomas@rediffmail.com | H3: 931 Christopher Ways Suite 833, North Michelle, IN 53484 | I3: OID7056 | J3: 45378 | K3: 01:46:33 | L3: PID015 | M3: 166.28 | N3: 4 | O3: FLAT8 | P3: 7 | Q3: 66 | R3: 45381 | S3: 18:46:26 | T3: =R3-J3 -> 3 | U3: =M3*N3 -> 665.12 | V3: =U3+Q3 -> 731.12 | W3: =IF(O3="FLAT8",0.08,IF(O3="FLAT10",0.1,IF(O3="FLAT15",0.15,IF(O3="FLAT20",0.2,0)))) -> 0.08 | X3: =V3*(1-W3) -> 672.6304 | Y3: =B3&" "&C3 -> Anthony Thomas | Z3: =IF(T3>P3,"Late",IF(T3<P3,"BeforeTime","Intime")) -> BeforeTime | AA3: =MID(G3,FIND("@",G3)+1,LEN(G3)-FIND("@",G3)) -> rediffmail.com
A4: CID115 | B4: Karl | C4: Gallagher | D4: 60 | E4: Other | F4: Phoenix | G4: karl.gallagher@rediffmail.com | H4: 5016 Snow Mountains Apt. 063, New Seanport, WY 41492 | I4: OID7502 | J4: 45342 | K4: 07:31:36 | L4: PID023 | M4: 202.54 | N4: 1 | O4: FLAT15 | P4: 3 | Q4: 47 | R4: 45344 | S4: 14:29:50 | T4: =R4-J4 -> 2 | U4: =M4*N4 -> 202.54 | V4: =U4+Q4 -> 249.54 | W4: =IF(O4="FLAT8",0.08,IF(O4="FLAT10",0.1,IF(O4="FLAT15",0.15,IF(O4="FLAT20",0.2,0)))) -> 0.15 | X4: =V4*(1-W4) -> 212.109 | Y4: =B4&" "&C4 -> Karl Gallagher | Z4: =IF(T4>P4,"Late",IF(T4<P4,"BeforeTime","Intime")) -> BeforeTime | AA4: =MID(G4,FIND("@",G4)+1,LEN(G4)-FIND("@",G4)) -> rediffmail.com
A5: CID115 | B5: Karl | C5: Gallagher | D5: 60 | E5: Other | F5: Phoenix | G5: karl.gallagher@rediffmail.com | H5: 5016 Snow Mountains Apt. 063, New Seanport, WY 41492 | I5: OID7077 | J5: 45426 | K5: 18:29:21 | L5: PID031 | M5: 405 | N5: 5 | O5: DEL0 | P5: 6 | Q5: 47 | R5: 45430 | S5: 07:00:32 | T5: =R5-J5 -> 4 | U5: =M5*N5 -> 2025 | V5: =U5+Q5 -> 2072 | W5: =IF(O5="FLAT8",0.08,IF(O5="FLAT10",0.1,IF(O5="FLAT15",0.15,IF(O5="FLAT20",0.2,0)))) -> 0 | X5: =V5*(1-W5) -> 2072 | Y5: =B5&" "&C5 -> Karl Gallagher | Z5: =IF(T5>P5,"Late",IF(T5<P5,"BeforeTime","Intime")) -> BeforeTime | AA5: =MID(G5,FIND("@",G5)+1,LEN(G5)-FIND("@",G5)) -> rediffmail.com
A6: CID149 | B6: Angela | C6: Horne | D6: 49 | E6: Other | F6: Phoenix | G6: angela.horne@outlook.com | H6: USNV Mueller, FPO AP 54648 | I6: OID2793 | J6: 45391 | K6: 03:23:21 | L6: PID015 | M6: 166.28 | N6: 1 | O6: FLAT8 | P6: 2 | Q6: 54 | R6: 45395 | S6: 22:10:58 | T6: =R6-J6 -> 4 | U6: =M6*N6 -> 166.28 | V6: =U6+Q6 -> 220.28 | W6: =IF(O6="FLAT8",0.08,IF(O6="FLAT10",0.1,IF(O6="FLAT15",0.15,IF(O6="FLAT20",0.2,0)))) -> 0.08 | X6: =V6*(1-W6) -> 202.6576 | Y6: =B6&" "&C6 -> Angela Horne | Z6: =IF(T6>P6,"Late",IF(T6<P6,"BeforeTime","Intime")) -> Late | AA6: =MID(G6,FIND("@",G6)+1,LEN(G6)-FIND("@",G6)) -> outlook.com
A7: CID159 | B7: Christine | C7: West | D7: 53 | E7: Other | F7: New York | G7: christine.west@gmail.com | H7: Unit 1433 Box 0246, DPO AP 94952 | I7: OID1483 | J7: 45543 | K7: 16:55:06 | L7: PID043 | M7: 330.11 | N7: 4 | O7: FLAT15 | P7: 6 | Q7: 39 | R7: 45547 | S7: 11:25:50 | T7: =R7-J7 -> 4 | U7: =M7*N7 -> 1320.44 | V7: =U7+Q7 -> 1359.44 | W7: =IF(O7="FLAT8",0.08,IF(O7="FLAT10",0.1,IF(O7="FLAT15",0.15,IF(O7="FLAT20",0.2,0)))) -> 0.15 | X7: =V7*(1-W7) -> 1155.524 | Y7: =B7&" "&C7 -> Christine West | Z7: =IF(T7>P7,"Late",IF(T7<P7,"BeforeTime","Intime")) -> BeforeTime | AA7: =MID(G7,FIND("@",G7)+1,LEN(G7)-FIND("@",G7)) -> gmail.com
A8: CID115 | B8: Karl | C8: Gallagher | D8: 60 | E8: Other | F8: Phoenix | G8: karl.gallagher@rediffmail.com | H8: 5016 Snow Mountains Apt. 063, New Seanport, WY 41492 | I8: OID4105 | J8: 45662 | K8: 09:47:21 | L8: PID022 | M8: 308.88 | N8: 5 | O8: FLAT20 | P8: 5 | Q8: 47 | R8: 45665 | S8: 20:10:50 | T8: =R8-J8 -> 3 | U8: =M8*N8 -> 1544.4 | V8: =U8+Q8 -> 1591.4 | W8: =IF(O8="FLAT8",0.08,IF(O8="FLAT10",0.1,IF(O8="FLAT15",0.15,IF(O8="FLAT20",0.2,0)))) -> 0.2 | X8: =V8*(1-W8) -> 1273.12 | Y8: =B8&" "&C8 -> Karl Gallagher | Z8: =IF(T8>P8,"Late",IF(T8<P8,"BeforeTime","Intime")) -> BeforeTime | AA8: =MID(G8,FIND("@",G8)+1,LEN(G8)-FIND("@",G8)) -> rediffmail.com
A9: CID198 | B9: David | C9: Delacruz | D9: 26 | E9: Female | F9: Los Angeles | G9: david.delacruz@rediffmail.com | H9: USNS Ray, FPO AE 20238 | I9: OID4372 | J9: 45459 | K9: 19:27:45 | L9: PID046 | M9: 363.64 | N9: 3 | O9: FLAT10 | P9: 2 | Q9: 70 | R9: 45464 | S9: 12:36:32 | T9: =R9-J9 -> 5 | U9: =M9*N9 -> 1090.92 | V9: =U9+Q9 -> 1160.92 | W9: =IF(O9="FLAT8",0.08,IF(O9="FLAT10",0.1,IF(O9="FLAT15",0.15,IF(O9="FLAT20",0.2,0)))) -> 0.1 | X9: =V9*(1-W9) -> 1044.828 | Y9: =B9&" "&C9 -> David Delacruz | Z9: =IF(T9>P9,"Late",IF(T9<P9,"BeforeTime","Intime")) -> Late | AA9: =MID(G9,FIND("@",G9)+1,LEN(G9)-FIND("@",G9)) -> rediffmail.com
A10: CID152 | B10: Marcus | C10: Valenzuela | D10: 39 | E10: Male | F10: Phoenix | G10: marcus.valenzuela@yahoo.com | H10: 694 Graham Prairie Apt. 887, Jimenezfurt, MI 33044 | I10: OID3528 | J10: 45040 | K10: 12:07:00 | L10: PID034 | M10: 275.44 | N10: 1 | O10: FLAT8 | P10: 7 | Q10: 63 | R10: 45042 | S10: 23:05:41 | T10: =R10-J10 -> 2 | U10: =M10*N10 -> 275.44 | V10: =U10+Q10 -> 338.44 | W10: =IF(O10="FLAT8",0.08,IF(O10="FLAT10",0.1,IF(O10="FLAT15",0.15,IF(O10="FLAT20",0.2,0)))) -> 0.08 | X10: =V10*(1-W10) -> 311.3648 | Y10: =B10&" "&C10 -> Marcus Valenzuela | Z10: =IF(T10>P10,"Late",IF(T10<P10,"BeforeTime","Intime")) -> BeforeTime | AA10: =MID(G10,FIND("@",G10)+1,LEN(G10)-FIND("@",G10)) -> yahoo.com
A11: CID130 | B11: Debra | C11: Rodriguez | D11: 48 | E11: Other | F11: Houston | G11: debra.rodriguez@rediffmail.com | H11: Unit 5964 Box 0721, DPO AP 01840 | I11: OID9634 | J11: 45282 | K11: 13:46:47 | L11: PID033 | M11: 48.45 | N11: 1 | O11: FLAT15 | P11: 7 | Q11: 59 | R11: 45287 | S11: 19:57:06 | T11: =R11-J11 -> 5 | U11: =M11*N11 -> 48.45 | V11: =U11+Q11 -> 107.45 | W11: =IF(O11="FLAT8",0.08,IF(O11="FLAT10",0.1,IF(O11="FLAT15",0.15,IF(O11="FLAT20",0.2,0)))) -> 0.15 | X11: =V11*(1-W11) -> 91.3325 | Y11: =B11&" "&C11 -> Debra Rodriguez | Z11: =IF(T11>P11,"Late",IF(T11<P11,"BeforeTime","Intime")) -> BeforeTime | AA11: =MID(G11,FIND("@",G11)+1,LEN(G11)-FIND("@",G11)) -> rediffmail.com
A12: CID115 | B12: Karl | C12: Gallagher | D12: 60 | E12: Other | F12: Phoenix | G12: karl.gallagher@rediffmail.com | H12: 5016 Snow Mountains Apt. 063, New Seanport, WY 41492 | I12: OID1905 | J12: 45588 | K12: 17:21:43 | L12: PID046 | M12: 363.64 | N12: 4 | O12: DEL0 | P12: 2 | Q12: 35 | R12: 45590 | S12: 08:00:35 | T12: =R12-J12 -> 2 | U12: =M12*N12 -> 1454.56 | V12: =U12+Q12 -> 1489.56 | W12: =IF(O12="FLAT8",0.08,IF(O12="FLAT10",0.1,IF(O12="FLAT15",0.15,IF(O12="FLAT20",0.2,0)))) -> 0 | X12: =V12*(1-W12) -> 1489.56 | Y12: =B12&" "&C12 -> Karl Gallagher | Z12: =IF(T12>P12,"Late",IF(T12<P12,"BeforeTime","Intime")) -> Intime | AA12: =MID(G12,FIND("@",G12)+1,LEN(G12)-FIND("@",G12)) -> rediffmail.com
A13: CID101 | B13: Bobby | C13: Forbes | D13: 20 | E13: Male | F13: Los Angeles | G13: bobby.forbes@gmail.com | H13: 3079 John Parkway Suite 961, Port Kristaview, MT 91019 | I13: OID3136 | J13: 45498 | K13: 15:09:49 | L13: PID007 | M13: 257.06 | N13: 3 | O13: DEL0 | P13: 7 | Q13: 62 | R13: 45499 | S13: 22:54:40 | T13: =R13-J13 -> 1 | U13: =M13*N13 -> 771.18 | V13: =U13+Q13 -> 833.18 | W13: =IF(O13="FLAT8",0.08,IF(O13="FLAT10",0.1,IF(O13="FLAT15",0.15,IF(O13="FLAT20",0.2,0)))) -> 0 | X13: =V13*(1-W13) -> 833.18 | Y13: =B13&" "&C13 -> Bobby Forbes | Z13: =IF(T13>P13,"Late",IF(T13<P13,"BeforeTime","Intime")) -> BeforeTime | AA13: =MID(G13,FIND("@",G13)+1,LEN(G13)-FIND("@",G13)) -> gmail.com
... A501: CID158 | B501: Angela | C501: Evans | D501: 52 | E501: Other | F501: Houston | G501: angela.evans@outlook.com | H501: 16031 David Mountain Suite 431, Susanborough, PA 01910 | I501: OID6847 | J501: 45501 | K501: 17:02:09 | L501: PID010 | M501: 44.5 | N501: 4 | O501: DEL0 | P501: 3 | Q501: 45 | R501: 45504 | S501: 05:55:32 | T501: =R501-J501 -> 3 | U501: =M501*N501 -> 178 | V501: =U501+Q501 -> 223 | W501: =IF(O501="FLAT8",0.08,IF(O501="FLAT10",0.1,IF(O501="FLAT15",0.15,IF(O501="FLAT20",0.2,0)))) -> 0 | X501: =V501*(1-W501) -> 223 | Y501: =B501&" "&C501 -> Angela Evans | Z501: =IF(T501>P501,"Late",IF(T501<P501,"BeforeTime","Intime")) -> Intime | AA501: =MID(G501,FIND("@",G501)+1,LEN(G501)-FIND("@",G501)) -> outlook.com

Sheet Project_Questions
B2: 1) Compute the following KPIs
B3: Customer KPIs | G3: Order and Delivery KPIs
B4: a) Find total unique customers | G4: a) Total Orders placed
B5: b) Customer id with most orders | G5: b) Average Days to Deliver
B6: c) Customer full name with highest total order amount | G6: c) Total orders with 0 Delivery Charge
B7: d) Average Customer Age
B10: Product KPIs
B11: a) Find total unique products
B12: b) Most ordered product
B13: c) Product which generated highest revenue
B16: Sales KPIs
B17: a) Sum Total Sales generated
B18: b) Sum Total Discount offered
B19: c) Total Sales after Discount
B20: d) Avg Sales(exclduing discount)
B22: Q2) Create a new column, Days to deliver and fill it with number of days it took for delivery
B24: Q3) Create a new Amount by using Price and Quantity
... B48: 10) Extract email from domain and represent its count on a bar chart

Sheet KPI_Dashboard
H1: E-COMMERCE KPIs DASHBOARD
B4: CUSTOMER KPIs | G4: PRODUCT KPIs | L4: SALES KPIs
B5: a) Total Unique Customers | G5: a) Total Unique Products | L5: a) Sum Total Sales Generated | N5: =SUM(data!U2:U501) -> 364289.49
D6: =COUNTA(_xlfn.UNIQUE(data!A2:A501)) -> 100 | I6: =COUNTA(_xlfn.UNIQUE(data!L2:L501)) -> 50
B7: b) Customer id with most orders | G7: b) Most Ordered Product (by Qty) | L7: b) Sum Total Discount Offered | N7: =SUMPRODUCT(data!V2:V501,data!W2:W501) -> 40687.91
D8: {=INDEX(_xlfn.UNIQUE(data!A2:A501),MATCH(MAX(COUNTIF(data!A2:A501,_xlfn.UNIQUE(data!A2:A501))),COUNTIF(data!A2:A501,_xlfn.UNIQUE(data!A2:A501)),0))} -> CID174 | I8: {=INDEX(data!L2:L501,MATCH(MAX(SUMIF(data!L2:L501,data!L2:L501,data!N2:N501)),SUMIF(data!L2:L501,data!L2:L501,data!N2:N501),0))} -> PID002
B9: c) Customer full name with highest total order amount | G9: c) Product - Highest Revenue | L9: c) Total Sales After Discount | N9: =SUM(data!X2:X501) -> 349724.58
D10: {=INDEX(data!Y2:Y501,MATCH(MAX(SUMIF(data!A2:A501,data!A2:A501,data!X2:X501)),SUMIF(data!A2:A501,data!A2:A501,data!X2:X501),0))} -> Jodi Whitney | I10: {=INDEX(data!L2:L501,MATCH(MAX(SUMIF(data!L2:L501,data!L2:L501,data!X2:X501)),SUMIF(data!L2:L501,data!L2:L501,data!X2:X501),0))} -> PID027
B11: d) Average Customer Age | L11: d) Avg Sales (excl. discount) | N11: =AVERAGE(data!U2:U501) -> 728.57898
D12: =AVERAGE(data!D2:D501) -> 42.124
C16: Order and Delivery KPIs
B17: a) Total Orders Placed | D17: =COUNTA(data!I2:I501) -> 500
B19: b) Average Days to Deliver | D19: =AVERAGE(data!T2:T501) -> 4.002
B21: c) Total Orders with 0 Delivery Charge (DEL0) | D21: =COUNTIF(data!O2:O501,"DEL0") -> 102

Sheet Visual_Analysis
A1: VISUAL ANALYSIS - CHARTS

Sheet Pivot_MonthGender
A1: Pivot Table: Month & Gender-wise Total Sales After Discount
A2: Month | B2: Female | C2: Male | D2: Other | E2: Grand Total
A3: 2023-02 | B3: 1080.95 | C3: 5634.55 | D3: 2246.05 | E3: 8961.55
A4: 2023-03 | B4: 3241.99 | C4: 3395.48 | D4: 5306.89 | E4: 11944.35
A5: 2023-04 | B5: 8393.67 | C5: 1878.39 | D5: 4602.16 | E5: 14874.23
A6: 2023-05 | B6: 2589.89 | C6: 3850.58 | D6: 3157.24 | E6: 9597.71
A7: 2023-06 | B7: 3144.38 | C7: 8283.18 | D7: 2963.04 | E7: 14390.6
A8: 2023-07 | B8: 5111.99 | C8: 7127.91 | D8: 8686.02 | E8: 20925.92
A9: 2023-08 | B9: 2849.58 | C9: 3629.32 | D9: 3753.56 | E9: 10232.46
A10: 2023-09 | B10: 3807.62 | C10: 5696.92 | D10: 4160.95 | E10: 13665.49
A11: 2023-10 | B11: 4174.71 | C11: 2936.91 | D11: 4474.56 | E11: 11586.18
A12: 2023-11 | B12: 1159.74 | C12: 4901 | D12: 7690.27 | E12: 13751
A13: 2023-12 | B13: 1824.81 | C13: 3244.41 | D13: 6250.1 | E13: 11319.31
A14: 2024-01 | B14: 1189.67 | C14: 2817.9 | D14: 7694.97 | E14: 11702.54
... A28: Grand Total | B28: 100990.45 | C28: 106227.25 | D28: 142506.88 | E28: 349724.58

Sheet Chart_Data
A1: chart 1: Top 10 Customers by Sales ===
A2: Customer | B2: Total Sales After Discount
A3: Jodi Whitney (CID174) | B3: 13121.12
A4: Lauren Crane (CID114) | B4: 8428.1
A5: Mark Summers (CID162) | B5: 7999.85
A6: Mary Knight (CID165) | B6: 7509.2
A7: Jessica Ruiz (CID102) | B7: 6873.93
A8: Angela Evans (CID158) | B8: 6840.93
A9: Lauren Long (CID191) | B9: 6810.7
A10: Katherine Weber (CID175) | B10: 6641.83
A11: John Herrera (CID182) | B11: 6640.58
A12: Brendan Kelly (CID113) | B12: 6587.07
A14: chart 2: Product Order Count ===
A15: Product | B15: Order Count
A16: PID036 | B16: 17
A17: PID046 | B17: 16
A18: PID048 | B18: 15
A19: PID027 | B19: 15
A20: PID018 | B20: 15
A21: PID041 | B21: 14
A22: PID002 | B22: 14
A23: PID017 | B23: 13
A24: PID013 | B24: 13
A25: PID014 | B25: 12
A26: PID043 | B26: 12
A27: PID033 | B27: 12
... A65: PID037 | B65: 6
A67: chart 3: City-wise Orders (Funnel) ===
A68: City | B68: Total Orders
A69: Houston | B69: 80
A70: Los Angeles | B70: 72
A71: San Francisco | B71: 72
A72: Phoenix | B72: 66
A73: Dallas | B73: 64
A74: Chicago | B74: 51
A75: New York | B75: 51
A76: Miami | B76: 44
A78: chart 4: City-wise Sales ===
A79: City | B79: Total Sales After Discount
A80: Houston | B80: 60581.07
...
